package com.trye.catche.finallye;



/**Here we are unable to reach to catch block of ArithmeticException 
   because before that only we are already handling by the Exception
   
   (Because Exception is Parent of ArithmeticException (child not able to handle the Parent))

 * @author SALEEM
 *
 */
public class Try_with_Multi_Catch_Blocks_PtoC_05 {

	public static void main(String[] args) {
		
		//tryCatch();
		

	}//main


}//Class


